Workbook
Name Slicer_Gender: #N/A
Name Slicer_Marital_Status: #N/A
Name Slicer_Overtime: #N/A

Sheet Main
A1: Employee ID | B1: Department ID | C1: JOB ID | D1: Attrition
A2: E001 | B2: D002 | C2: J03 | D2: No
A3: E002 | B3: D003 | C3: J07 | D3: No
A4: E003 | B4: D004 | C4: J09 | D4: Yes
A5: E004 | B5: D003 | C5: J08 | D5: No
A6: E005 | B6: D006 | C6: J11 | D6: Yes
A7: E006 | B7: D005 | C7: J05 | D7: No | G7: śś
A8: E007 | B8: D002 | C8: J04 | D8: No
A9: E008 | B9: D005 | C9: J03 | D9: No
A10: E009 | B10: D006 | C10: J11 | D10: No
A11: E010 | B11: D006 | C11: J11 | D11: No
A12: E011 | B12: D003 | C12: J07 | D12: No
A13: E012 | B13: D002 | C13: J03 | D13: No
A14: E013 | B14: D002 | C14: J04 | D14: Yes
A15: E014 | B15: D004 | C15: J10 | D15: No
A16: E015 | B16: D006 | C16: J11 | D16: No
A17: E016 | B17: D002 | C17: J03 | D17: No
A18: E017 | B18: D005 | C18: J05 | D18: No
A19: E018 | B19: D005 | C19: J06 | D19: Yes
... A51: E050 | B51: D006 | C51: J12 | D51: No

Sheet Employee
A1: Employee name | B1: Employee id | C1: Gender | D1: Education | E1: Salary | F1: Rating | G1: Total Year of Experience | H1: Overtime | I1: Overtime Incentive | J1: Salary ( After overtime ) | K1: Marital Status
A2: Aarav Sharma | B2: E001 | C2: Male | D2: B.Tech | E2: 120000 | F2: {=_xlfn.SWITCH(TRUE(), E2>=160000,5, E2>=110000,4, E2>=90000,3, E2>=60000,2, 1 )} -> 4 | G2: 7 | H2: 2 | I2: {=_xlfn.SWITCH(TRUE(), H2=2,20, H2=1,10, H2=3,30, "-" )} -> 20 | J2: =IF(ISNUMBER(E2+E2*I2%),E2+E2*I2%,E2) -> 144000 | K2: Unmarried
A3: Vivaan Gupta | B3: E002 | C3: Male | D3: B.Com | E3: 60000 | F3: {=_xlfn.SWITCH(TRUE(), E3>=160000,5, E3>=110000,4, E3>=90000,3, E3>=60000,2, 1 )} -> 2 | G3: 2 | H3: - | I3: {=_xlfn.SWITCH(TRUE(), H3=2,20, H3=1,10, H3=3,30, "-" )} -> - | J3: =IF(ISNUMBER(E3+E3*I3%),E3+E3*I3%,E3) -> 60000 | K3: Unmarried
A4: Aditya Verma | B4: E003 | C4: Male | D4: B.Com | E4: 60000 | F4: {=_xlfn.SWITCH(TRUE(), E4>=160000,5, E4>=110000,4, E4>=90000,3, E4>=60000,2, 1 )} -> 2 | G4: 3 | H4: - | I4: {=_xlfn.SWITCH(TRUE(), H4=2,20, H4=1,10, H4=3,30, "-" )} -> - | J4: =IF(ISNUMBER(E4+E4*I4%),E4+E4*I4%,E4) -> 60000 | K4: Married
A5: Rohan Mehta | B5: E004 | C5: Male | D5: B.Tech | E5: 120000 | F5: {=_xlfn.SWITCH(TRUE(), E5>=160000,5, E5>=110000,4, E5>=90000,3, E5>=60000,2, 1 )} -> 4 | G5: 9 | H5: - | I5: {=_xlfn.SWITCH(TRUE(), H5=2,20, H5=1,10, H5=3,30, "-" )} -> - | J5: =IF(ISNUMBER(E5+E5*I5%),E5+E5*I5%,E5) -> 120000 | K5: Married
A6: Karan Malhotra | B6: E005 | C6: Male | D6: BBA | E6: 80000 | F6: {=_xlfn.SWITCH(TRUE(), E6>=160000,5, E6>=110000,4, E6>=90000,3, E6>=60000,2, 1 )} -> 2 | G6: 1 | H6: - | I6: {=_xlfn.SWITCH(TRUE(), H6=2,20, H6=1,10, H6=3,30, "-" )} -> - | J6: =IF(ISNUMBER(E6+E6*I6%),E6+E6*I6%,E6) -> 80000 | K6: Unmarried
A7: Arjun Kapoor | B7: E006 | C7: Male | D7: BA | E7: 50000 | F7: {=_xlfn.SWITCH(TRUE(), E7>=160000,5, E7>=110000,4, E7>=90000,3, E7>=60000,2, 1 )} -> 1 | G7: 1 | H7: 2 | I7: {=_xlfn.SWITCH(TRUE(), H7=2,20, H7=1,10, H7=3,30, "-" )} -> 20 | J7: =IF(ISNUMBER(E7+E7*I7%),E7+E7*I7%,E7) -> 60000 | K7: Married
A8: Rahul Bansal | B8: E007 | C8: Male | D8: B.Tech | E8: 50000 | F8: {=_xlfn.SWITCH(TRUE(), E8>=160000,5, E8>=110000,4, E8>=90000,3, E8>=60000,2, 1 )} -> 1 | G8: 1 | H8: - | I8: {=_xlfn.SWITCH(TRUE(), H8=2,20, H8=1,10, H8=3,30, "-" )} -> - | J8: =IF(ISNUMBER(E8+E8*I8%),E8+E8*I8%,E8) -> 50000 | K8: Unmarried
A9: Siddharth Jain | B9: E008 | C9: Male | D9: M.Sc. | E9: 110000 | F9: {=_xlfn.SWITCH(TRUE(), E9>=160000,5, E9>=110000,4, E9>=90000,3, E9>=60000,2, 1 )} -> 4 | G9: 6 | H9: - | I9: {=_xlfn.SWITCH(TRUE(), H9=2,20, H9=1,10, H9=3,30, "-" )} -> - | J9: =IF(ISNUMBER(E9+E9*I9%),E9+E9*I9%,E9) -> 110000 | K9: Unmarried
A10: Ayush Agarwal | B10: E009 | C10: Male | D10: BBA | E10: 60000 | F10: {=_xlfn.SWITCH(TRUE(), E10>=160000,5, E10>=110000,4, E10>=90000,3, E10>=60000,2, 1 )} -> 2 | G10: 3 | H10: - | I10: {=_xlfn.SWITCH(TRUE(), H10=2,20, H10=1,10, H10=3,30, "-" )} -> - | J10: =IF(ISNUMBER(E10+E10*I10%),E10+E10*I10%,E10) -> 60000 | K10: Unmarried
A11: Nikhil Khanna | B11: E010 | C11: Male | D11: BA | E11: 80000 | F11: {=_xlfn.SWITCH(TRUE(), E11>=160000,5, E11>=110000,4, E11>=90000,3, E11>=60000,2, 1 )} -> 2 | G11: 3 | H11: 1 | I11: {=_xlfn.SWITCH(TRUE(), H11=2,20, H11=1,10, H11=3,30, "-" )} -> 10 | J11: =IF(ISNUMBER(E11+E11*I11%),E11+E11*I11%,E11) -> 88000 | K11: Married
A12: Priya Sharma | B12: E011 | C12: Female | D12: B.Tech | E12: 120000 | F12: {=_xlfn.SWITCH(TRUE(), E12>=160000,5, E12>=110000,4, E12>=90000,3, E12>=60000,2, 1 )} -> 4 | G12: 6 | H12: 3 | I12: {=_xlfn.SWITCH(TRUE(), H12=2,20, H12=1,10, H12=3,30, "-" )} -> 30 | J12: =IF(ISNUMBER(E12+E12*I12%),E12+E12*I12%,E12) -> 156000 | K12: Unmarried
A13: Ananya Gupta | B13: E012 | C13: Female | D13: M.Sc. | E13: 160000 | F13: {=_xlfn.SWITCH(TRUE(), E13>=160000,5, E13>=110000,4, E13>=90000,3, E13>=60000,2, 1 )} -> 5 | G13: 12 | H13: - | I13: {=_xlfn.SWITCH(TRUE(), H13=2,20, H13=1,10, H13=3,30, "-" )} -> - | J13: =IF(ISNUMBER(E13+E13*I13%),E13+E13*I13%,E13) -> 160000 | K13: Unmarried
A14: Sneha Verma | B14: E013 | C14: Female | D14: B.Tech | E14: 80000 | F14: {=_xlfn.SWITCH(TRUE(), E14>=160000,5, E14>=110000,4, E14>=90000,3, E14>=60000,2, 1 )} -> 2 | G14: 3 | H14: - | I14: {=_xlfn.SWITCH(TRUE(), H14=2,20, H14=1,10, H14=3,30, "-" )} -> - | J14: =IF(ISNUMBER(E14+E14*I14%),E14+E14*I14%,E14) -> 80000 | K14: Unmarried
A15: Riya Kapoor | B15: E014 | C15: Female | D15: B.Tech | E15: 120000 | F15: {=_xlfn.SWITCH(TRUE(), E15>=160000,5, E15>=110000,4, E15>=90000,3, E15>=60000,2, 1 )} -> 4 | G15: 8 | H15: 2 | I15: {=_xlfn.SWITCH(TRUE(), H15=2,20, H15=1,10, H15=3,30, "-" )} -> 20 | J15: =IF(ISNUMBER(E15+E15*I15%),E15+E15*I15%,E15) -> 144000 | K15: Unmarried
A16: Neha Mehta | B16: E015 | C16: Female | D16: B.Tech | E16: 80000 | F16: {=_xlfn.SWITCH(TRUE(), E16>=160000,5, E16>=110000,4, E16>=90000,3, E16>=60000,2, 1 )} -> 2 | G16: 1 | H16: 1 | I16: {=_xlfn.SWITCH(TRUE(), H16=2,20, H16=1,10, H16=3,30, "-" )} -> 10 | J16: =IF(ISNUMBER(E16+E16*I16%),E16+E16*I16%,E16) -> 88000 | K16: Unmarried
A17: Aditi Jain | B17: E016 | C17: Female | D17: BBA | E17: 80000 | F17: {=_xlfn.SWITCH(TRUE(), E17>=160000,5, E17>=110000,4, E17>=90000,3, E17>=60000,2, 1 )} -> 2 | G17: 3 | H17: - | I17: {=_xlfn.SWITCH(TRUE(), H17=2,20, H17=1,10, H17=3,30, "-" )} -> - | J17: =IF(ISNUMBER(E17+E17*I17%),E17+E17*I17%,E17) -> 80000 | K17: Unmarried
A18: Pooja Malhotra | B18: E017 | C18: Female | D18: BA | E18: 120000 | F18: {=_xlfn.SWITCH(TRUE(), E18>=160000,5, E18>=110000,4, E18>=90000,3, E18>=60000,2, 1 )} -> 4 | G18: 6 | H18: 3 | I18: {=_xlfn.SWITCH(TRUE(), H18=2,20, H18=1,10, H18=3,30, "-" )} -> 30 | J18: =IF(ISNUMBER(E18+E18*I18%),E18+E18*I18%,E18) -> 156000 | K18: Unmarried
A19: Kavya Bansal | B19: E018 | C19: Female | D19: M.Sc. | E19: 160000 | F19: {=_xlfn.SWITCH(TRUE(), E19>=160000,5, E19>=110000,4, E19>=90000,3, E19>=60000,2, 1 )} -> 5 | G19: 12 | H19: - | I19: {=_xlfn.SWITCH(TRUE(), H19=2,20, H19=1,10, H19=3,30, "-" )} -> - | J19: =IF(ISNUMBER(E19+E19*I19%),E19+E19*I19%,E19) -> 160000 | K19: Married
A20: Simran Arora | B20: E019 | C20: Female | D20: B.Tech | E20: 120000 | F20: {=_xlfn.SWITCH(TRUE(), E20>=160000,5, E20>=110000,4, E20>=90000,3, E20>=60000,2, 1 )} -> 4 | G20: 6 | H20: - | I20: {=_xlfn.SWITCH(TRUE(), H20=2,20, H20=1,10, H20=3,30, "-" )} -> - | J20: =IF(ISNUMBER(E20+E20*I20%),E20+E20*I20%,E20) -> 120000 | K20: Unmarried
A21: Muskan Gupta | B21: E020 | C21: Female | D21: B.Tech | E21: 120000 | F21: {=_xlfn.SWITCH(TRUE(), E21>=160000,5, E21>=110000,4, E21>=90000,3, E21>=60000,2, 1 )} -> 4 | G21: 9 | H21: 2 | I21: {=_xlfn.SWITCH(TRUE(), H21=2,20, H21=1,10, H21=3,30, "-" )} -> 20 | J21: =IF(ISNUMBER(E21+E21*I21%),E21+E21*I21%,E21) -> 144000 | K21: Unmarried
A22: Yash Singh | B22: E021 | C22: Male | D22: B.Com | E22: 80000 | F22: {=_xlfn.SWITCH(TRUE(), E22>=160000,5, E22>=110000,4, E22>=90000,3, E22>=60000,2, 1 )} -> 2 | G22: 2 | H22: 2 | I22: {=_xlfn.SWITCH(TRUE(), H22=2,20, H22=1,10, H22=3,30, "-" )} -> 20 | J22: =IF(ISNUMBER(E22+E22*I22%),E22+E22*I22%,E22) -> 96000 | K22: Unmarried
A23: Harsh Patel | B23: E022 | C23: Male | D23: B.Sc. | E23: 60000 | F23: {=_xlfn.SWITCH(TRUE(), E23>=160000,5, E23>=110000,4, E23>=90000,3, E23>=60000,2, 1 )} -> 2 | G23: 3 | H23: - | I23: {=_xlfn.SWITCH(TRUE(), H23=2,20, H23=1,10, H23=3,30, "-" )} -> - | J23: =IF(ISNUMBER(E23+E23*I23%),E23+E23*I23%,E23) -> 60000 | K23: Unmarried
A24: Manav Arora | B24: E023 | C24: Male | D24: B.Com | E24: 60000 | F24: {=_xlfn.SWITCH(TRUE(), E24>=160000,5, E24>=110000,4, E24>=90000,3, E24>=60000,2, 1 )} -> 2 | G24: 1 | H24: 2 | I24: {=_xlfn.SWITCH(TRUE(), H24=2,20, H24=1,10, H24=3,30, "-" )} -> 20 | J24: =IF(ISNUMBER(E24+E24*I24%),E24+E24*I24%,E24) -> 72000 | K24: Unmarried
A25: Ishaan Sethi | B25: E024 | C25: Female | D25: B.Sc. | E25: 60000 | F25: {=_xlfn.SWITCH(TRUE(), E25>=160000,5, E25>=110000,4, E25>=90000,3, E25>=60000,2, 1 )} -> 2 | G25: 1 | H25: - | I25: {=_xlfn.SWITCH(TRUE(), H25=2,20, H25=1,10, H25=3,30, "-" )} -> - | J25: =IF(ISNUMBER(E25+E25*I25%),E25+E25*I25%,E25) -> 60000 | K25: Married
A26: Laksh Gupta | B26: E025 | C26: Male | D26: MBA | E26: 90000 | F26: {=_xlfn.SWITCH(TRUE(), E26>=160000,5, E26>=110000,4, E26>=90000,3, E26>=60000,2, 1 )} -> 3 | G26: 4 | H26: 2 | I26: {=_xlfn.SWITCH(TRUE(), H26=2,20, H26=1,10, H26=3,30, "-" )} -> 20 | J26: =IF(ISNUMBER(E26+E26*I26%),E26+E26*I26%,E26) -> 108000 | K26: Unmarried
A27: Tanish Kapoor | B27: E026 | C27: Male | D27: MBA | E27: 90000 | F27: {=_xlfn.SWITCH(TRUE(), E27>=160000,5, E27>=110000,4, E27>=90000,3, E27>=60000,2, 1 )} -> 3 | G27: 4 | H27: - | I27: {=_xlfn.SWITCH(TRUE(), H27=2,20, H27=1,10, H27=3,30, "-" )} -> - | J27: =IF(ISNUMBER(E27+E27*I27%),E27+E27*I27%,E27) -> 90000 | K27: Married
A28: Dev Malhotra | B28: E027 | C28: Male | D28: B.Tech | E28: 80000 | F28: {=_xlfn.SWITCH(TRUE(), E28>=160000,5, E28>=110000,4, E28>=90000,3, E28>=60000,2, 1 )} -> 2 | G28: 1 | H28: - | I28: {=_xlfn.SWITCH(TRUE(), H28=2,20, H28=1,10, H28=3,30, "-" )} -> - | J28: =IF(ISNUMBER(E28+E28*I28%),E28+E28*I28%,E28) -> 80000 | K28: Unmarried
A29: Pranav Goyal | B29: E028 | C29: Male | D29: B.Tech | E29: 120000 | F29: {=_xlfn.SWITCH(TRUE(), E29>=160000,5, E29>=110000,4, E29>=90000,3, E29>=60000,2, 1 )} -> 4 | G29: 9 | H29: - | I29: {=_xlfn.SWITCH(TRUE(), H29=2,20, H29=1,10, H29=3,30, "-" )} -> - | J29: =IF(ISNUMBER(E29+E29*I29%),E29+E29*I29%,E29) -> 120000 | K29: Unmarried
A30: Varun Khurana | B30: E029 | C30: Male | D30: B.Sc. | E30: 90000 | F30: {=_xlfn.SWITCH(TRUE(), E30>=160000,5, E30>=110000,4, E30>=90000,3, E30>=60000,2, 1 )} -> 3 | G30: 5 | H30: - | I30: {=_xlfn.SWITCH(TRUE(), H30=2,20, H30=1,10, H30=3,30, "-" )} -> - | J30: =IF(ISNUMBER(E30+E30*I30%),E30+E30*I30%,E30) -> 90000 | K30: Married
A31: Rishabh Arora | B31: E030 | C31: Male | D31: BA | E31: 50000 | F31: {=_xlfn.SWITCH(TRUE(), E31>=160000,5, E31>=110000,4, E31>=90000,3, E31>=60000,2, 1 )} -> 1 | G31: 1 | H31: 3 | I31: {=_xlfn.SWITCH(TRUE(), H31=2,20, H31=1,10, H31=3,30, "-" )} -> 30 | J31: =IF(ISNUMBER(E31+E31*I31%),E31+E31*I31%,E31) -> 65000 | K31: Married
A32: Meera Khanna | B32: E031 | C32: Female | D32: BA | E32: 120000 | F32: {=_xlfn.SWITCH(TRUE(), E32>=160000,5, E32>=110000,4, E32>=90000,3, E32>=60000,2, 1 )} -> 4 | G32: 8 | H32: - | I32: {=_xlfn.SWITCH(TRUE(), H32=2,20, H32=1,10, H32=3,30, "-" )} -> - | J32: =IF(ISNUMBER(E32+E32*I32%),E32+E32*I32%,E32) -> 120000 | K32: Married
A33: Naina Sethi | B33: E032 | C33: Female | D33: B.Sc. | E33: 90000 | F33: {=_xlfn.SWITCH(TRUE(), E33>=160000,5, E33>=110000,4, E33>=90000,3, E33>=60000,2, 1 )} -> 3 | G33: 4 | H33: - | I33: {=_xlfn.SWITCH(TRUE(), H33=2,20, H33=1,10, H33=3,30, "-" )} -> - | J33: =IF(ISNUMBER(E33+E33*I33%),E33+E33*I33%,E33) -> 90000 | K33: Unmarried
A34: Diya Sharma | B34: E033 | C34: Female | D34: B.Tech | E34: 50000 | F34: {=_xlfn.SWITCH(TRUE(), E34>=160000,5, E34>=110000,4, E34>=90000,3, E34>=60000,2, 1 )} -> 1 | G34: 2 | H34: - | I34: {=_xlfn.SWITCH(TRUE(), H34=2,20, H34=1,10, H34=3,30, "-" )} -> - | J34: =IF(ISNUMBER(E34+E34*I34%),E34+E34*I34%,E34) -> 50000 | K34: Unmarried
A35: Isha Arora | B35: E034 | C35: Female | D35: B.Sc. | E35: 120000 | F35: {=_xlfn.SWITCH(TRUE(), E35>=160000,5, E35>=110000,4, E35>=90000,3, E35>=60000,2, 1 )} -> 4 | G35: 9 | H35: - | I35: {=_xlfn.SWITCH(TRUE(), H35=2,20, H35=1,10, H35=3,30, "-" )} -> - | J35: =IF(ISNUMBER(E35+E35*I35%),E35+E35*I35%,E35) -> 120000 | K35: Unmarried
A36: Tanvi Goyal | B36: E035 | C36: Female | D36: B.Com | E36: 60000 | F36: {=_xlfn.SWITCH(TRUE(), E36>=160000,5, E36>=110000,4, E36>=90000,3, E36>=60000,2, 1 )} -> 2 | G36: 1 | H36: - | I36: {=_xlfn.SWITCH(TRUE(), H36=2,20, H36=1,10, H36=3,30, "-" )} -> - | J36: =IF(ISNUMBER(E36+E36*I36%),E36+E36*I36%,E36) -> 60000 | K36: Unmarried
A37: Sakshi Verma | B37: E036 | C37: Female | D37: MBA | E37: 90000 | F37: {=_xlfn.SWITCH(TRUE(), E37>=160000,5, E37>=110000,4, E37>=90000,3, E37>=60000,2, 1 )} -> 3 | G37: 5 | H37: 3 | I37: {=_xlfn.SWITCH(TRUE(), H37=2,20, H37=1,10, H37=3,30, "-" )} -> 30 | J37: =IF(ISNUMBER(E37+E37*I37%),E37+E37*I37%,E37) -> 117000 | K37: Married
A38: Ritika Gupta | B38: E037 | C38: Female | D38: B.Sc. | E38: 120000 | F38: {=_xlfn.SWITCH(TRUE(), E38>=160000,5, E38>=110000,4, E38>=90000,3, E38>=60000,2, 1 )} -> 4 | G38: 9 | H38: - | I38: {=_xlfn.SWITCH(TRUE(), H38=2,20, H38=1,10, H38=3,30, "-" )} -> - | J38: =IF(ISNUMBER(E38+E38*I38%),E38+E38*I38%,E38) -> 120000 | K38: Married
A39: Khushi Jain | B39: E038 | C39: Female | D39: B.Tech | E39: 120000 | F39: {=_xlfn.SWITCH(TRUE(), E39>=160000,5, E39>=110000,4, E39>=90000,3, E39>=60000,2, 1 )} -> 4 | G39: 6 | H39: 3 | I39: {=_xlfn.SWITCH(TRUE(), H39=2,20, H39=1,10, H39=3,30, "-" )} -> 30 | J39: =IF(ISNUMBER(E39+E39*I39%),E39+E39*I39%,E39) -> 156000 | K39: Unmarried
A40: Aisha Kapoor | B40: E039 | C40: Female | D40: Ph.D | E40: 50000 | F40: {=_xlfn.SWITCH(TRUE(), E40>=160000,5, E40>=110000,4, E40>=90000,3, E40>=60000,2, 1 )} -> 1 | G40: 1 | H40: - | I40: {=_xlfn.SWITCH(TRUE(), H40=2,20, H40=1,10, H40=3,30, "-" )} -> - | J40: =IF(ISNUMBER(E40+E40*I40%),E40+E40*I40%,E40) -> 50000 | K40: Unmarried
...

Sheet Department
A1: Department | B1: Department id
A2: HR | B2: D001
A3: Finance | B3: D002
A4: Sales Depo | B4: D003
A5: Marketing | B5: D004
A6: IT | B6: D005
A7: Operations | B7: D006

Sheet JOB
A1: Job ID | B1: Job
A2: J01 | B2: HR Executive
A3: J02 | B3: Recruiter
A4: J03 | B4: Accountant
A5: J04 | B5: Financial Analyst
A6: J05 | B6: Software Engineer
A7: J06 | B7: Data Analyst
A8: J07 | B8: Sales Executive
A9: J08 | B9: Sales Manager
A10: J09 | B10: Marketing Executive
A11: J10 | B11: Digital Marketer
A12: J11 | B12: Operations Executive
A13: J12 | B13: Operations Manager

Sheet Lookup Table ignore
A1: {=_xlfn._xlws.FILTER(Main!A1:B51,Main!B1:B51="D001")} -> E026 | B1: D001 | C1: J01
A2: E028 | B2: D001 | C2: J02
A3: E041 | B3: D001 | C3: J02
A4: E042 | B4: D001 | C4: J01
A5: {=_xlfn._xlws.FILTER(Main!A1:B51,Main!B1:B51="D002")} -> E001 | B5: D002 | C5: J03
A6: E007 | B6: D002 | C6: J04
A7: E012 | B7: D002 | C7: J03
A8: E013 | B8: D002 | C8: J04
A9: E016 | B9: D002 | C9: J03
A10: E020 | B10: D002 | C10: J03
A11: E031 | B11: D002 | C11: J04
A12: E035 | B12: D002 | C12: J04
A13: {=_xlfn._xlws.FILTER(Main!A1:B51,Main!B1:B51="D003")} -> E002 | B13: D003 | C13: J07
A14: E004 | B14: D003 | C14: J08
A15: E011 | B15: D003 | C15: J07
A16: E030 | B16: D003 | C16: J08
A17: E037 | B17: D003 | C17: J07
A18: E040 | B18: D003 | C18: J08
A19: E044 | B19: D003 | C19: J07
A20: E046 | B20: D003 | C20: J08
A21: E047 | B21: D003 | C21: J07
A22: E049 | B22: D003 | C22: J08
A23: {=_xlfn._xlws.FILTER(Main!A1:B51,Main!B1:B51="D004")} -> E003 | B23: D004 | C23: J09
A24: E014 | B24: D004 | C24: J10
A25: E019 | B25: D004 | C25: J09
A26: E021 | B26: D004 | C26: J10
A27: E022 | B27: D004 | C27: J09
A28: E027 | B28: D004 | C28: J10
A29: E032 | B29: D004 | C29: J09
A30: E033 | B30: D004 | C30: J10
A31: E039 | B31: D004 | C31: J09
A32: {=_xlfn._xlws.FILTER(Main!A1:B51,Main!B1:B51="D005")} -> E006 | B32: D005 | C32: J05
A33: E008 | B33: D005 | C33: J06
A34: E017 | B34: D005 | C34: J05
A35: E018 | B35: D005 | C35: J06
A36: E024 | B36: D005 | C36: J05
A37: E034 | B37: D005 | C37: J06
A38: E048 | B38: D005 | C38: J05
A39: {=_xlfn._xlws.FILTER(Main!A1:B51,Main!B1:B51="D006")} -> E005 | B39: D006 | C39: J11
A40: E009 | B40: D006 | C40: J11
...

Sheet pivot
A1: Row Labels | B1: Count of Employee id | D1: Row Labels | E1: Count of Employee id
A2: Female | B2: 26 | D2: Married | E2: 13 | G2: Row Labels | H2: Count of Employee id
A3: Male | B3: 24 | D3: Unmarried | E3: 37 | G3: Operations Executive | H3: 9
A4: Grand Total | B4: 50 | D4: Grand Total | E4: 50 | G4: Sales Executive | H4: 5
G5: Sales Manager | H5: 5
A6: Row Labels | B6: Attrition Count | G6: Accountant | H6: 5
A7: Marketing | B7: 3 | D7: Row Labels | E7: Count of Attrition | G7: Marketing Executive | H7: 5
A8: Operations | B8: 3 | D8: Yes | E8: 0.2 | G8: Financial Analyst | H8: 4
A9: Sales Depo | B9: 1 | D9: No | E9: 0.8 | G9: Software Engineer | H9: 4
A10: HR | B10: 1 | D10: Grand Total | E10: 1 | G10: Digital Marketer | H10: 4
A11: Finance | B11: 1 | G11: Operations Manager | H11: 3
A12: IT | B12: 1 | G12: HR Executive | H12: 2
A13: Grand Total | B13: 10 | D13: Avg.Salary | E13: AVG. Rating | G13: Data Analyst | H13: 2
D14: 89200 | E14: 2.68 | G14: Recruiter | H14: 2
G15: Grand Total | H15: 50
A16: Row Labels | B16: Count of Employee id | D16: Count of Employee id | E16: Attrition Count
A17: Operations | B17: 12 | D17: 50 | E17: 10
A18: Sales Depo | B18: 10 | G18: No of employee
A19: Marketing | B19: 9 | D19: Avg.Experience | G19: 50
A20: Finance | B20: 8 | D20: 4.28
A21: IT | B21: 7
A22: HR | B22: 4
A23: Grand Total | B23: 50

Sheet KPI
A1: KPI
A3: =pivot!D13 -> Avg.Salary | B3: =pivot!D14 -> 89200
A4: =pivot!D16 -> Count of Employee id | B4: =pivot!D17 -> 50
A5: =pivot!E13 -> AVG. Rating | B5: =pivot!E14 -> 2.68
A6: =pivot!G18 -> No of employee | B6: =pivot!G19 -> 50
A7: Avg.experience | B7: =pivot!D20 -> 4.28
A9: INSIGHTS
A10: Proportions of male to female
A11: in which department , employyess are the highest
A12: attrition rate

Sheet DashBoard
AC21: v
